{
 "cells": [
  {
   "cell_type": "markdown",
   "metadata": {},
   "source": [
    "# Non-Traffic Citations\n",
    "## Prepared by: Renhan Xu"
   ]
  },
  {
   "cell_type": "markdown",
   "metadata": {},
   "source": [
    "----\n",
    "### Package Import\n",
    "To start this notebook, I am going to import pandas, as well as other packages I will need for this project."
   ]
  },
  {
   "cell_type": "code",
   "execution_count": null,
   "metadata": {},
   "outputs": [
    {
     "name": "stderr",
     "output_type": "stream",
     "text": [
      "ERROR:root:Internal Python error in the inspect module.\n",
      "Below is the traceback from this internal error.\n",
      "\n",
      "ERROR:root:Internal Python error in the inspect module.\n",
      "Below is the traceback from this internal error.\n",
      "\n",
      "ERROR:root:Internal Python error in the inspect module.\n",
      "Below is the traceback from this internal error.\n",
      "\n"
     ]
    },
    {
     "name": "stdout",
     "output_type": "stream",
     "text": [
      "Traceback (most recent call last):\n",
      "  File \"/opt/tljh/user/lib/python3.8/site-packages/IPython/core/interactiveshell.py\", line 3343, in run_code\n",
      "    exec(code_obj, self.user_global_ns, self.user_ns)\n",
      "  File \"<ipython-input-1-73ba0c5db5ba>\", line 5, in <module>\n",
      "    get_ipython().run_line_magic('matplotlib', 'inline')\n",
      "  File \"/opt/tljh/user/lib/python3.8/site-packages/IPython/core/interactiveshell.py\", line 2326, in run_line_magic\n",
      "    result = fn(*args, **kwargs)\n",
      "  File \"<decorator-gen-108>\", line 2, in matplotlib\n",
      "  File \"/opt/tljh/user/lib/python3.8/site-packages/IPython/core/magic.py\", line 187, in <lambda>\n",
      "    call = lambda f, *a, **k: f(*a, **k)\n",
      "  File \"/opt/tljh/user/lib/python3.8/site-packages/IPython/core/magics/pylab.py\", line 99, in matplotlib\n",
      "    gui, backend = self.shell.enable_matplotlib(args.gui.lower() if isinstance(args.gui, str) else args.gui)\n",
      "  File \"/opt/tljh/user/lib/python3.8/site-packages/IPython/core/interactiveshell.py\", line 3419, in enable_matplotlib\n",
      "    gui, backend = pt.find_gui_and_backend(gui, self.pylab_gui_select)\n",
      "  File \"/opt/tljh/user/lib/python3.8/site-packages/IPython/core/pylabtools.py\", line 280, in find_gui_and_backend\n",
      "    import matplotlib\n",
      "  File \"/opt/tljh/user/lib/python3.8/site-packages/matplotlib/__init__.py\", line 1015, in <module>\n",
      "    rcParams = rc_params()\n",
      "  File \"/opt/tljh/user/lib/python3.8/site-packages/matplotlib/__init__.py\", line 878, in rc_params\n",
      "    return rc_params_from_file(matplotlib_fname(), fail_on_error)\n",
      "  File \"/opt/tljh/user/lib/python3.8/site-packages/matplotlib/__init__.py\", line 731, in matplotlib_fname\n",
      "    for fname in gen_candidates():\n",
      "  File \"/opt/tljh/user/lib/python3.8/site-packages/matplotlib/__init__.py\", line 720, in gen_candidates\n",
      "    yield os.path.join(os.getcwd(), 'matplotlibrc')\n",
      "FileNotFoundError: [Errno 2] No such file or directory\n",
      "\n",
      "During handling of the above exception, another exception occurred:\n",
      "\n",
      "Traceback (most recent call last):\n",
      "  File \"/opt/tljh/user/lib/python3.8/site-packages/IPython/core/interactiveshell.py\", line 2044, in showtraceback\n",
      "    stb = value._render_traceback_()\n",
      "AttributeError: 'FileNotFoundError' object has no attribute '_render_traceback_'\n",
      "\n",
      "During handling of the above exception, another exception occurred:\n",
      "\n",
      "Traceback (most recent call last):\n",
      "  File \"/opt/tljh/user/lib/python3.8/site-packages/IPython/core/ultratb.py\", line 1169, in get_records\n",
      "    return _fixed_getinnerframes(etb, number_of_lines_of_context, tb_offset)\n",
      "  File \"/opt/tljh/user/lib/python3.8/site-packages/IPython/core/ultratb.py\", line 316, in wrapped\n",
      "    return f(*args, **kwargs)\n",
      "  File \"/opt/tljh/user/lib/python3.8/site-packages/IPython/core/ultratb.py\", line 350, in _fixed_getinnerframes\n",
      "    records = fix_frame_records_filenames(inspect.getinnerframes(etb, context))\n",
      "  File \"/opt/tljh/user/lib/python3.8/inspect.py\", line 1503, in getinnerframes\n",
      "    frameinfo = (tb.tb_frame,) + getframeinfo(tb, context)\n",
      "  File \"/opt/tljh/user/lib/python3.8/inspect.py\", line 1461, in getframeinfo\n",
      "    filename = getsourcefile(frame) or getfile(frame)\n",
      "  File \"/opt/tljh/user/lib/python3.8/inspect.py\", line 708, in getsourcefile\n",
      "    if getattr(getmodule(object, filename), '__loader__', None) is not None:\n",
      "  File \"/opt/tljh/user/lib/python3.8/inspect.py\", line 737, in getmodule\n",
      "    file = getabsfile(object, _filename)\n",
      "  File \"/opt/tljh/user/lib/python3.8/inspect.py\", line 721, in getabsfile\n",
      "    return os.path.normcase(os.path.abspath(_filename))\n",
      "  File \"/opt/tljh/user/lib/python3.8/posixpath.py\", line 379, in abspath\n",
      "    cwd = os.getcwd()\n",
      "FileNotFoundError: [Errno 2] No such file or directory\n",
      "Traceback (most recent call last):\n",
      "  File \"/opt/tljh/user/lib/python3.8/site-packages/IPython/core/interactiveshell.py\", line 3343, in run_code\n",
      "    exec(code_obj, self.user_global_ns, self.user_ns)\n",
      "  File \"<ipython-input-1-73ba0c5db5ba>\", line 5, in <module>\n",
      "    get_ipython().run_line_magic('matplotlib', 'inline')\n",
      "  File \"/opt/tljh/user/lib/python3.8/site-packages/IPython/core/interactiveshell.py\", line 2326, in run_line_magic\n",
      "    result = fn(*args, **kwargs)\n",
      "  File \"<decorator-gen-108>\", line 2, in matplotlib\n",
      "  File \"/opt/tljh/user/lib/python3.8/site-packages/IPython/core/magic.py\", line 187, in <lambda>\n",
      "    call = lambda f, *a, **k: f(*a, **k)\n",
      "  File \"/opt/tljh/user/lib/python3.8/site-packages/IPython/core/magics/pylab.py\", line 99, in matplotlib\n",
      "    gui, backend = self.shell.enable_matplotlib(args.gui.lower() if isinstance(args.gui, str) else args.gui)\n",
      "  File \"/opt/tljh/user/lib/python3.8/site-packages/IPython/core/interactiveshell.py\", line 3419, in enable_matplotlib\n",
      "    gui, backend = pt.find_gui_and_backend(gui, self.pylab_gui_select)\n",
      "  File \"/opt/tljh/user/lib/python3.8/site-packages/IPython/core/pylabtools.py\", line 280, in find_gui_and_backend\n",
      "    import matplotlib\n",
      "  File \"/opt/tljh/user/lib/python3.8/site-packages/matplotlib/__init__.py\", line 1015, in <module>\n",
      "    rcParams = rc_params()\n",
      "  File \"/opt/tljh/user/lib/python3.8/site-packages/matplotlib/__init__.py\", line 878, in rc_params\n",
      "    return rc_params_from_file(matplotlib_fname(), fail_on_error)\n",
      "  File \"/opt/tljh/user/lib/python3.8/site-packages/matplotlib/__init__.py\", line 731, in matplotlib_fname\n",
      "    for fname in gen_candidates():\n",
      "  File \"/opt/tljh/user/lib/python3.8/site-packages/matplotlib/__init__.py\", line 720, in gen_candidates\n",
      "    yield os.path.join(os.getcwd(), 'matplotlibrc')\n",
      "FileNotFoundError: [Errno 2] No such file or directory\n",
      "\n",
      "During handling of the above exception, another exception occurred:\n",
      "\n",
      "Traceback (most recent call last):\n",
      "  File \"/opt/tljh/user/lib/python3.8/site-packages/IPython/core/interactiveshell.py\", line 2044, in showtraceback\n",
      "    stb = value._render_traceback_()\n",
      "AttributeError: 'FileNotFoundError' object has no attribute '_render_traceback_'\n",
      "\n",
      "During handling of the above exception, another exception occurred:\n",
      "\n",
      "Traceback (most recent call last):\n",
      "  File \"/opt/tljh/user/lib/python3.8/site-packages/IPython/core/interactiveshell.py\", line 3263, in run_ast_nodes\n",
      "    if (await self.run_code(code, result,  async_=asy)):\n",
      "  File \"/opt/tljh/user/lib/python3.8/site-packages/IPython/core/interactiveshell.py\", line 3360, in run_code\n",
      "    self.showtraceback(running_compiled_code=True)\n",
      "  File \"/opt/tljh/user/lib/python3.8/site-packages/IPython/core/interactiveshell.py\", line 2046, in showtraceback\n",
      "    stb = self.InteractiveTB.structured_traceback(etype,\n",
      "  File \"/opt/tljh/user/lib/python3.8/site-packages/IPython/core/ultratb.py\", line 1435, in structured_traceback\n",
      "    return FormattedTB.structured_traceback(\n",
      "  File \"/opt/tljh/user/lib/python3.8/site-packages/IPython/core/ultratb.py\", line 1335, in structured_traceback\n",
      "    return VerboseTB.structured_traceback(\n",
      "  File \"/opt/tljh/user/lib/python3.8/site-packages/IPython/core/ultratb.py\", line 1192, in structured_traceback\n",
      "    formatted_exception = self.format_exception_as_a_whole(etype, evalue, etb, number_of_lines_of_context,\n",
      "  File \"/opt/tljh/user/lib/python3.8/site-packages/IPython/core/ultratb.py\", line 1150, in format_exception_as_a_whole\n",
      "    last_unique, recursion_repeat = find_recursion(orig_etype, evalue, records)\n",
      "  File \"/opt/tljh/user/lib/python3.8/site-packages/IPython/core/ultratb.py\", line 451, in find_recursion\n",
      "    return len(records), 0\n",
      "TypeError: object of type 'NoneType' has no len()\n",
      "\n",
      "During handling of the above exception, another exception occurred:\n",
      "\n",
      "Traceback (most recent call last):\n",
      "  File \"/opt/tljh/user/lib/python3.8/site-packages/IPython/core/interactiveshell.py\", line 2044, in showtraceback\n",
      "    stb = value._render_traceback_()\n",
      "AttributeError: 'TypeError' object has no attribute '_render_traceback_'\n",
      "\n",
      "During handling of the above exception, another exception occurred:\n",
      "\n",
      "Traceback (most recent call last):\n",
      "  File \"/opt/tljh/user/lib/python3.8/site-packages/IPython/core/ultratb.py\", line 1169, in get_records\n",
      "    return _fixed_getinnerframes(etb, number_of_lines_of_context, tb_offset)\n",
      "  File \"/opt/tljh/user/lib/python3.8/site-packages/IPython/core/ultratb.py\", line 316, in wrapped\n",
      "    return f(*args, **kwargs)\n",
      "  File \"/opt/tljh/user/lib/python3.8/site-packages/IPython/core/ultratb.py\", line 350, in _fixed_getinnerframes\n",
      "    records = fix_frame_records_filenames(inspect.getinnerframes(etb, context))\n",
      "  File \"/opt/tljh/user/lib/python3.8/inspect.py\", line 1503, in getinnerframes\n",
      "    frameinfo = (tb.tb_frame,) + getframeinfo(tb, context)\n",
      "  File \"/opt/tljh/user/lib/python3.8/inspect.py\", line 1461, in getframeinfo\n",
      "    filename = getsourcefile(frame) or getfile(frame)\n",
      "  File \"/opt/tljh/user/lib/python3.8/inspect.py\", line 708, in getsourcefile\n",
      "    if getattr(getmodule(object, filename), '__loader__', None) is not None:\n",
      "  File \"/opt/tljh/user/lib/python3.8/inspect.py\", line 737, in getmodule\n",
      "    file = getabsfile(object, _filename)\n",
      "  File \"/opt/tljh/user/lib/python3.8/inspect.py\", line 721, in getabsfile\n",
      "    return os.path.normcase(os.path.abspath(_filename))\n",
      "  File \"/opt/tljh/user/lib/python3.8/posixpath.py\", line 379, in abspath\n",
      "    cwd = os.getcwd()\n",
      "FileNotFoundError: [Errno 2] No such file or directory\n",
      "ERROR! Session/line number was not unique in database. History logging moved to new session 109\n",
      "Traceback (most recent call last):\n",
      "  File \"/opt/tljh/user/lib/python3.8/site-packages/IPython/core/interactiveshell.py\", line 3343, in run_code\n",
      "    exec(code_obj, self.user_global_ns, self.user_ns)\n",
      "  File \"<ipython-input-1-73ba0c5db5ba>\", line 5, in <module>\n",
      "    get_ipython().run_line_magic('matplotlib', 'inline')\n",
      "  File \"/opt/tljh/user/lib/python3.8/site-packages/IPython/core/interactiveshell.py\", line 2326, in run_line_magic\n",
      "    result = fn(*args, **kwargs)\n",
      "  File \"<decorator-gen-108>\", line 2, in matplotlib\n",
      "  File \"/opt/tljh/user/lib/python3.8/site-packages/IPython/core/magic.py\", line 187, in <lambda>\n",
      "    call = lambda f, *a, **k: f(*a, **k)\n",
      "  File \"/opt/tljh/user/lib/python3.8/site-packages/IPython/core/magics/pylab.py\", line 99, in matplotlib\n",
      "    gui, backend = self.shell.enable_matplotlib(args.gui.lower() if isinstance(args.gui, str) else args.gui)\n",
      "  File \"/opt/tljh/user/lib/python3.8/site-packages/IPython/core/interactiveshell.py\", line 3419, in enable_matplotlib\n",
      "    gui, backend = pt.find_gui_and_backend(gui, self.pylab_gui_select)\n",
      "  File \"/opt/tljh/user/lib/python3.8/site-packages/IPython/core/pylabtools.py\", line 280, in find_gui_and_backend\n",
      "    import matplotlib\n",
      "  File \"/opt/tljh/user/lib/python3.8/site-packages/matplotlib/__init__.py\", line 1015, in <module>\n",
      "    rcParams = rc_params()\n",
      "  File \"/opt/tljh/user/lib/python3.8/site-packages/matplotlib/__init__.py\", line 878, in rc_params\n",
      "    return rc_params_from_file(matplotlib_fname(), fail_on_error)\n",
      "  File \"/opt/tljh/user/lib/python3.8/site-packages/matplotlib/__init__.py\", line 731, in matplotlib_fname\n",
      "    for fname in gen_candidates():\n",
      "  File \"/opt/tljh/user/lib/python3.8/site-packages/matplotlib/__init__.py\", line 720, in gen_candidates\n",
      "    yield os.path.join(os.getcwd(), 'matplotlibrc')\n",
      "FileNotFoundError: [Errno 2] No such file or directory\n",
      "\n",
      "During handling of the above exception, another exception occurred:\n",
      "\n",
      "Traceback (most recent call last):\n",
      "  File \"/opt/tljh/user/lib/python3.8/site-packages/IPython/core/interactiveshell.py\", line 2044, in showtraceback\n",
      "    stb = value._render_traceback_()\n",
      "AttributeError: 'FileNotFoundError' object has no attribute '_render_traceback_'\n",
      "\n",
      "During handling of the above exception, another exception occurred:\n",
      "\n",
      "Traceback (most recent call last):\n",
      "  File \"/opt/tljh/user/lib/python3.8/site-packages/IPython/core/interactiveshell.py\", line 3263, in run_ast_nodes\n",
      "    if (await self.run_code(code, result,  async_=asy)):\n",
      "  File \"/opt/tljh/user/lib/python3.8/site-packages/IPython/core/interactiveshell.py\", line 3360, in run_code\n",
      "    self.showtraceback(running_compiled_code=True)\n",
      "  File \"/opt/tljh/user/lib/python3.8/site-packages/IPython/core/interactiveshell.py\", line 2046, in showtraceback\n",
      "    stb = self.InteractiveTB.structured_traceback(etype,\n",
      "  File \"/opt/tljh/user/lib/python3.8/site-packages/IPython/core/ultratb.py\", line 1435, in structured_traceback\n",
      "    return FormattedTB.structured_traceback(\n",
      "  File \"/opt/tljh/user/lib/python3.8/site-packages/IPython/core/ultratb.py\", line 1335, in structured_traceback\n",
      "    return VerboseTB.structured_traceback(\n",
      "  File \"/opt/tljh/user/lib/python3.8/site-packages/IPython/core/ultratb.py\", line 1192, in structured_traceback\n",
      "    formatted_exception = self.format_exception_as_a_whole(etype, evalue, etb, number_of_lines_of_context,\n",
      "  File \"/opt/tljh/user/lib/python3.8/site-packages/IPython/core/ultratb.py\", line 1150, in format_exception_as_a_whole\n",
      "    last_unique, recursion_repeat = find_recursion(orig_etype, evalue, records)\n",
      "  File \"/opt/tljh/user/lib/python3.8/site-packages/IPython/core/ultratb.py\", line 451, in find_recursion\n",
      "    return len(records), 0\n",
      "TypeError: object of type 'NoneType' has no len()\n",
      "\n",
      "During handling of the above exception, another exception occurred:\n",
      "\n",
      "Traceback (most recent call last):\n",
      "  File \"/opt/tljh/user/lib/python3.8/site-packages/IPython/core/interactiveshell.py\", line 2044, in showtraceback\n",
      "    stb = value._render_traceback_()\n",
      "AttributeError: 'TypeError' object has no attribute '_render_traceback_'\n",
      "\n",
      "During handling of the above exception, another exception occurred:\n",
      "\n",
      "Traceback (most recent call last):\n",
      "  File \"/opt/tljh/user/lib/python3.8/site-packages/IPython/core/interactiveshell.py\", line 2895, in _run_cell\n",
      "    return runner(coro)\n",
      "  File \"/opt/tljh/user/lib/python3.8/site-packages/IPython/core/async_helpers.py\", line 68, in _pseudo_sync_runner\n",
      "    coro.send(None)\n",
      "  File \"/opt/tljh/user/lib/python3.8/site-packages/IPython/core/interactiveshell.py\", line 3071, in run_cell_async\n",
      "    has_raised = await self.run_ast_nodes(code_ast.body, cell_name,\n",
      "  File \"/opt/tljh/user/lib/python3.8/site-packages/IPython/core/interactiveshell.py\", line 3282, in run_ast_nodes\n",
      "    self.showtraceback()\n",
      "  File \"/opt/tljh/user/lib/python3.8/site-packages/IPython/core/interactiveshell.py\", line 2046, in showtraceback\n",
      "    stb = self.InteractiveTB.structured_traceback(etype,\n",
      "  File \"/opt/tljh/user/lib/python3.8/site-packages/IPython/core/ultratb.py\", line 1435, in structured_traceback\n",
      "    return FormattedTB.structured_traceback(\n",
      "  File \"/opt/tljh/user/lib/python3.8/site-packages/IPython/core/ultratb.py\", line 1335, in structured_traceback\n",
      "    return VerboseTB.structured_traceback(\n",
      "  File \"/opt/tljh/user/lib/python3.8/site-packages/IPython/core/ultratb.py\", line 1210, in structured_traceback\n",
      "    formatted_exceptions += self.format_exception_as_a_whole(etype, evalue, etb, lines_of_context,\n",
      "  File \"/opt/tljh/user/lib/python3.8/site-packages/IPython/core/ultratb.py\", line 1150, in format_exception_as_a_whole\n",
      "    last_unique, recursion_repeat = find_recursion(orig_etype, evalue, records)\n",
      "  File \"/opt/tljh/user/lib/python3.8/site-packages/IPython/core/ultratb.py\", line 451, in find_recursion\n",
      "    return len(records), 0\n",
      "TypeError: object of type 'NoneType' has no len()\n",
      "\n",
      "During handling of the above exception, another exception occurred:\n",
      "\n",
      "Traceback (most recent call last):\n",
      "  File \"/opt/tljh/user/lib/python3.8/site-packages/IPython/core/interactiveshell.py\", line 2044, in showtraceback\n",
      "    stb = value._render_traceback_()\n",
      "AttributeError: 'TypeError' object has no attribute '_render_traceback_'\n",
      "\n",
      "During handling of the above exception, another exception occurred:\n",
      "\n",
      "Traceback (most recent call last):\n",
      "  File \"/opt/tljh/user/lib/python3.8/site-packages/IPython/core/ultratb.py\", line 1169, in get_records\n",
      "    return _fixed_getinnerframes(etb, number_of_lines_of_context, tb_offset)\n",
      "  File \"/opt/tljh/user/lib/python3.8/site-packages/IPython/core/ultratb.py\", line 316, in wrapped\n",
      "    return f(*args, **kwargs)\n",
      "  File \"/opt/tljh/user/lib/python3.8/site-packages/IPython/core/ultratb.py\", line 350, in _fixed_getinnerframes\n",
      "    records = fix_frame_records_filenames(inspect.getinnerframes(etb, context))\n",
      "  File \"/opt/tljh/user/lib/python3.8/inspect.py\", line 1503, in getinnerframes\n",
      "    frameinfo = (tb.tb_frame,) + getframeinfo(tb, context)\n",
      "  File \"/opt/tljh/user/lib/python3.8/inspect.py\", line 1461, in getframeinfo\n",
      "    filename = getsourcefile(frame) or getfile(frame)\n",
      "  File \"/opt/tljh/user/lib/python3.8/inspect.py\", line 708, in getsourcefile\n",
      "    if getattr(getmodule(object, filename), '__loader__', None) is not None:\n",
      "  File \"/opt/tljh/user/lib/python3.8/inspect.py\", line 737, in getmodule\n",
      "    file = getabsfile(object, _filename)\n",
      "  File \"/opt/tljh/user/lib/python3.8/inspect.py\", line 721, in getabsfile\n",
      "    return os.path.normcase(os.path.abspath(_filename))\n",
      "  File \"/opt/tljh/user/lib/python3.8/posixpath.py\", line 379, in abspath\n",
      "    cwd = os.getcwd()\n",
      "FileNotFoundError: [Errno 2] No such file or directory\n"
     ]
    }
   ],
   "source": [
    "# Import packages\n",
    "import operator\n",
    "import pandas as pd\n",
    "import numpy as np\n",
    "%matplotlib inline\n",
    "import matplotlib.pyplot as plt"
   ]
  },
  {
   "cell_type": "markdown",
   "metadata": {},
   "source": [
    "----\n",
    "### Loading the Data\n",
    "Next, I am going to load the data."
   ]
  },
  {
   "cell_type": "code",
   "execution_count": null,
   "metadata": {},
   "outputs": [
    {
     "name": "stderr",
     "output_type": "stream",
     "text": [
      "ERROR:root:Internal Python error in the inspect module.\n",
      "Below is the traceback from this internal error.\n",
      "\n",
      "ERROR:root:Internal Python error in the inspect module.\n",
      "Below is the traceback from this internal error.\n",
      "\n",
      "ERROR:root:Internal Python error in the inspect module.\n",
      "Below is the traceback from this internal error.\n",
      "\n"
     ]
    },
    {
     "name": "stdout",
     "output_type": "stream",
     "text": [
      "Traceback (most recent call last):\n",
      "  File \"/opt/tljh/user/lib/python3.8/site-packages/IPython/core/interactiveshell.py\", line 3343, in run_code\n",
      "    exec(code_obj, self.user_global_ns, self.user_ns)\n",
      "  File \"<ipython-input-1-008153ea0ac2>\", line 2, in <module>\n",
      "    non_traffic_citations = pd.read_csv(\"NonTrafficCitations.csv\") # index_col=\"_id\")\n",
      "  File \"/opt/tljh/user/lib/python3.8/site-packages/pandas/io/parsers.py\", line 676, in parser_f\n",
      "    return _read(filepath_or_buffer, kwds)\n",
      "  File \"/opt/tljh/user/lib/python3.8/site-packages/pandas/io/parsers.py\", line 448, in _read\n",
      "    parser = TextFileReader(fp_or_buf, **kwds)\n",
      "  File \"/opt/tljh/user/lib/python3.8/site-packages/pandas/io/parsers.py\", line 880, in __init__\n",
      "    self._make_engine(self.engine)\n",
      "  File \"/opt/tljh/user/lib/python3.8/site-packages/pandas/io/parsers.py\", line 1114, in _make_engine\n",
      "    self._engine = CParserWrapper(self.f, **self.options)\n",
      "  File \"/opt/tljh/user/lib/python3.8/site-packages/pandas/io/parsers.py\", line 1891, in __init__\n",
      "    self._reader = parsers.TextReader(src, **kwds)\n",
      "  File \"pandas/_libs/parsers.pyx\", line 374, in pandas._libs.parsers.TextReader.__cinit__\n",
      "  File \"pandas/_libs/parsers.pyx\", line 674, in pandas._libs.parsers.TextReader._setup_parser_source\n",
      "FileNotFoundError: [Errno 2] File NonTrafficCitations.csv does not exist: 'NonTrafficCitations.csv'\n",
      "\n",
      "During handling of the above exception, another exception occurred:\n",
      "\n",
      "Traceback (most recent call last):\n",
      "  File \"/opt/tljh/user/lib/python3.8/site-packages/IPython/core/interactiveshell.py\", line 2044, in showtraceback\n",
      "    stb = value._render_traceback_()\n",
      "AttributeError: 'FileNotFoundError' object has no attribute '_render_traceback_'\n",
      "\n",
      "During handling of the above exception, another exception occurred:\n",
      "\n",
      "Traceback (most recent call last):\n",
      "  File \"/opt/tljh/user/lib/python3.8/site-packages/IPython/core/ultratb.py\", line 1169, in get_records\n",
      "    return _fixed_getinnerframes(etb, number_of_lines_of_context, tb_offset)\n",
      "  File \"/opt/tljh/user/lib/python3.8/site-packages/IPython/core/ultratb.py\", line 316, in wrapped\n",
      "    return f(*args, **kwargs)\n",
      "  File \"/opt/tljh/user/lib/python3.8/site-packages/IPython/core/ultratb.py\", line 350, in _fixed_getinnerframes\n",
      "    records = fix_frame_records_filenames(inspect.getinnerframes(etb, context))\n",
      "  File \"/opt/tljh/user/lib/python3.8/inspect.py\", line 1503, in getinnerframes\n",
      "    frameinfo = (tb.tb_frame,) + getframeinfo(tb, context)\n",
      "  File \"/opt/tljh/user/lib/python3.8/inspect.py\", line 1461, in getframeinfo\n",
      "    filename = getsourcefile(frame) or getfile(frame)\n",
      "  File \"/opt/tljh/user/lib/python3.8/inspect.py\", line 708, in getsourcefile\n",
      "    if getattr(getmodule(object, filename), '__loader__', None) is not None:\n",
      "  File \"/opt/tljh/user/lib/python3.8/inspect.py\", line 737, in getmodule\n",
      "    file = getabsfile(object, _filename)\n",
      "  File \"/opt/tljh/user/lib/python3.8/inspect.py\", line 721, in getabsfile\n",
      "    return os.path.normcase(os.path.abspath(_filename))\n",
      "  File \"/opt/tljh/user/lib/python3.8/posixpath.py\", line 379, in abspath\n",
      "    cwd = os.getcwd()\n",
      "FileNotFoundError: [Errno 2] No such file or directory\n",
      "Traceback (most recent call last):\n",
      "  File \"/opt/tljh/user/lib/python3.8/site-packages/IPython/core/interactiveshell.py\", line 3343, in run_code\n",
      "    exec(code_obj, self.user_global_ns, self.user_ns)\n",
      "  File \"<ipython-input-1-008153ea0ac2>\", line 2, in <module>\n",
      "    non_traffic_citations = pd.read_csv(\"NonTrafficCitations.csv\") # index_col=\"_id\")\n",
      "  File \"/opt/tljh/user/lib/python3.8/site-packages/pandas/io/parsers.py\", line 676, in parser_f\n",
      "    return _read(filepath_or_buffer, kwds)\n",
      "  File \"/opt/tljh/user/lib/python3.8/site-packages/pandas/io/parsers.py\", line 448, in _read\n",
      "    parser = TextFileReader(fp_or_buf, **kwds)\n",
      "  File \"/opt/tljh/user/lib/python3.8/site-packages/pandas/io/parsers.py\", line 880, in __init__\n",
      "    self._make_engine(self.engine)\n",
      "  File \"/opt/tljh/user/lib/python3.8/site-packages/pandas/io/parsers.py\", line 1114, in _make_engine\n",
      "    self._engine = CParserWrapper(self.f, **self.options)\n",
      "  File \"/opt/tljh/user/lib/python3.8/site-packages/pandas/io/parsers.py\", line 1891, in __init__\n",
      "    self._reader = parsers.TextReader(src, **kwds)\n",
      "  File \"pandas/_libs/parsers.pyx\", line 374, in pandas._libs.parsers.TextReader.__cinit__\n",
      "  File \"pandas/_libs/parsers.pyx\", line 674, in pandas._libs.parsers.TextReader._setup_parser_source\n",
      "FileNotFoundError: [Errno 2] File NonTrafficCitations.csv does not exist: 'NonTrafficCitations.csv'\n",
      "\n",
      "During handling of the above exception, another exception occurred:\n",
      "\n",
      "Traceback (most recent call last):\n",
      "  File \"/opt/tljh/user/lib/python3.8/site-packages/IPython/core/interactiveshell.py\", line 2044, in showtraceback\n",
      "    stb = value._render_traceback_()\n",
      "AttributeError: 'FileNotFoundError' object has no attribute '_render_traceback_'\n",
      "\n",
      "During handling of the above exception, another exception occurred:\n",
      "\n",
      "Traceback (most recent call last):\n",
      "  File \"/opt/tljh/user/lib/python3.8/site-packages/IPython/core/interactiveshell.py\", line 3263, in run_ast_nodes\n",
      "    if (await self.run_code(code, result,  async_=asy)):\n",
      "  File \"/opt/tljh/user/lib/python3.8/site-packages/IPython/core/interactiveshell.py\", line 3360, in run_code\n",
      "    self.showtraceback(running_compiled_code=True)\n",
      "  File \"/opt/tljh/user/lib/python3.8/site-packages/IPython/core/interactiveshell.py\", line 2046, in showtraceback\n",
      "    stb = self.InteractiveTB.structured_traceback(etype,\n",
      "  File \"/opt/tljh/user/lib/python3.8/site-packages/IPython/core/ultratb.py\", line 1435, in structured_traceback\n",
      "    return FormattedTB.structured_traceback(\n",
      "  File \"/opt/tljh/user/lib/python3.8/site-packages/IPython/core/ultratb.py\", line 1335, in structured_traceback\n",
      "    return VerboseTB.structured_traceback(\n",
      "  File \"/opt/tljh/user/lib/python3.8/site-packages/IPython/core/ultratb.py\", line 1192, in structured_traceback\n",
      "    formatted_exception = self.format_exception_as_a_whole(etype, evalue, etb, number_of_lines_of_context,\n",
      "  File \"/opt/tljh/user/lib/python3.8/site-packages/IPython/core/ultratb.py\", line 1150, in format_exception_as_a_whole\n",
      "    last_unique, recursion_repeat = find_recursion(orig_etype, evalue, records)\n",
      "  File \"/opt/tljh/user/lib/python3.8/site-packages/IPython/core/ultratb.py\", line 451, in find_recursion\n",
      "    return len(records), 0\n",
      "TypeError: object of type 'NoneType' has no len()\n",
      "\n",
      "During handling of the above exception, another exception occurred:\n",
      "\n",
      "Traceback (most recent call last):\n",
      "  File \"/opt/tljh/user/lib/python3.8/site-packages/IPython/core/interactiveshell.py\", line 2044, in showtraceback\n",
      "    stb = value._render_traceback_()\n",
      "AttributeError: 'TypeError' object has no attribute '_render_traceback_'\n",
      "\n",
      "During handling of the above exception, another exception occurred:\n",
      "\n",
      "Traceback (most recent call last):\n",
      "  File \"/opt/tljh/user/lib/python3.8/site-packages/IPython/core/ultratb.py\", line 1169, in get_records\n",
      "    return _fixed_getinnerframes(etb, number_of_lines_of_context, tb_offset)\n",
      "  File \"/opt/tljh/user/lib/python3.8/site-packages/IPython/core/ultratb.py\", line 316, in wrapped\n",
      "    return f(*args, **kwargs)\n",
      "  File \"/opt/tljh/user/lib/python3.8/site-packages/IPython/core/ultratb.py\", line 350, in _fixed_getinnerframes\n",
      "    records = fix_frame_records_filenames(inspect.getinnerframes(etb, context))\n",
      "  File \"/opt/tljh/user/lib/python3.8/inspect.py\", line 1503, in getinnerframes\n",
      "    frameinfo = (tb.tb_frame,) + getframeinfo(tb, context)\n",
      "  File \"/opt/tljh/user/lib/python3.8/inspect.py\", line 1461, in getframeinfo\n",
      "    filename = getsourcefile(frame) or getfile(frame)\n",
      "  File \"/opt/tljh/user/lib/python3.8/inspect.py\", line 708, in getsourcefile\n",
      "    if getattr(getmodule(object, filename), '__loader__', None) is not None:\n",
      "  File \"/opt/tljh/user/lib/python3.8/inspect.py\", line 737, in getmodule\n",
      "    file = getabsfile(object, _filename)\n",
      "  File \"/opt/tljh/user/lib/python3.8/inspect.py\", line 721, in getabsfile\n",
      "    return os.path.normcase(os.path.abspath(_filename))\n",
      "  File \"/opt/tljh/user/lib/python3.8/posixpath.py\", line 379, in abspath\n",
      "    cwd = os.getcwd()\n",
      "FileNotFoundError: [Errno 2] No such file or directory\n",
      "ERROR! Session/line number was not unique in database. History logging moved to new session 107\n",
      "Traceback (most recent call last):\n",
      "  File \"/opt/tljh/user/lib/python3.8/site-packages/IPython/core/interactiveshell.py\", line 3343, in run_code\n",
      "    exec(code_obj, self.user_global_ns, self.user_ns)\n",
      "  File \"<ipython-input-1-008153ea0ac2>\", line 2, in <module>\n",
      "    non_traffic_citations = pd.read_csv(\"NonTrafficCitations.csv\") # index_col=\"_id\")\n",
      "  File \"/opt/tljh/user/lib/python3.8/site-packages/pandas/io/parsers.py\", line 676, in parser_f\n",
      "    return _read(filepath_or_buffer, kwds)\n",
      "  File \"/opt/tljh/user/lib/python3.8/site-packages/pandas/io/parsers.py\", line 448, in _read\n",
      "    parser = TextFileReader(fp_or_buf, **kwds)\n",
      "  File \"/opt/tljh/user/lib/python3.8/site-packages/pandas/io/parsers.py\", line 880, in __init__\n",
      "    self._make_engine(self.engine)\n",
      "  File \"/opt/tljh/user/lib/python3.8/site-packages/pandas/io/parsers.py\", line 1114, in _make_engine\n",
      "    self._engine = CParserWrapper(self.f, **self.options)\n",
      "  File \"/opt/tljh/user/lib/python3.8/site-packages/pandas/io/parsers.py\", line 1891, in __init__\n",
      "    self._reader = parsers.TextReader(src, **kwds)\n",
      "  File \"pandas/_libs/parsers.pyx\", line 374, in pandas._libs.parsers.TextReader.__cinit__\n",
      "  File \"pandas/_libs/parsers.pyx\", line 674, in pandas._libs.parsers.TextReader._setup_parser_source\n",
      "FileNotFoundError: [Errno 2] File NonTrafficCitations.csv does not exist: 'NonTrafficCitations.csv'\n",
      "\n",
      "During handling of the above exception, another exception occurred:\n",
      "\n",
      "Traceback (most recent call last):\n",
      "  File \"/opt/tljh/user/lib/python3.8/site-packages/IPython/core/interactiveshell.py\", line 2044, in showtraceback\n",
      "    stb = value._render_traceback_()\n",
      "AttributeError: 'FileNotFoundError' object has no attribute '_render_traceback_'\n",
      "\n",
      "During handling of the above exception, another exception occurred:\n",
      "\n",
      "Traceback (most recent call last):\n",
      "  File \"/opt/tljh/user/lib/python3.8/site-packages/IPython/core/interactiveshell.py\", line 3263, in run_ast_nodes\n",
      "    if (await self.run_code(code, result,  async_=asy)):\n",
      "  File \"/opt/tljh/user/lib/python3.8/site-packages/IPython/core/interactiveshell.py\", line 3360, in run_code\n",
      "    self.showtraceback(running_compiled_code=True)\n",
      "  File \"/opt/tljh/user/lib/python3.8/site-packages/IPython/core/interactiveshell.py\", line 2046, in showtraceback\n",
      "    stb = self.InteractiveTB.structured_traceback(etype,\n",
      "  File \"/opt/tljh/user/lib/python3.8/site-packages/IPython/core/ultratb.py\", line 1435, in structured_traceback\n",
      "    return FormattedTB.structured_traceback(\n",
      "  File \"/opt/tljh/user/lib/python3.8/site-packages/IPython/core/ultratb.py\", line 1335, in structured_traceback\n",
      "    return VerboseTB.structured_traceback(\n",
      "  File \"/opt/tljh/user/lib/python3.8/site-packages/IPython/core/ultratb.py\", line 1192, in structured_traceback\n",
      "    formatted_exception = self.format_exception_as_a_whole(etype, evalue, etb, number_of_lines_of_context,\n",
      "  File \"/opt/tljh/user/lib/python3.8/site-packages/IPython/core/ultratb.py\", line 1150, in format_exception_as_a_whole\n",
      "    last_unique, recursion_repeat = find_recursion(orig_etype, evalue, records)\n",
      "  File \"/opt/tljh/user/lib/python3.8/site-packages/IPython/core/ultratb.py\", line 451, in find_recursion\n",
      "    return len(records), 0\n",
      "TypeError: object of type 'NoneType' has no len()\n",
      "\n",
      "During handling of the above exception, another exception occurred:\n",
      "\n",
      "Traceback (most recent call last):\n",
      "  File \"/opt/tljh/user/lib/python3.8/site-packages/IPython/core/interactiveshell.py\", line 2044, in showtraceback\n",
      "    stb = value._render_traceback_()\n",
      "AttributeError: 'TypeError' object has no attribute '_render_traceback_'\n",
      "\n",
      "During handling of the above exception, another exception occurred:\n",
      "\n",
      "Traceback (most recent call last):\n",
      "  File \"/opt/tljh/user/lib/python3.8/site-packages/IPython/core/interactiveshell.py\", line 2895, in _run_cell\n",
      "    return runner(coro)\n",
      "  File \"/opt/tljh/user/lib/python3.8/site-packages/IPython/core/async_helpers.py\", line 68, in _pseudo_sync_runner\n",
      "    coro.send(None)\n",
      "  File \"/opt/tljh/user/lib/python3.8/site-packages/IPython/core/interactiveshell.py\", line 3071, in run_cell_async\n",
      "    has_raised = await self.run_ast_nodes(code_ast.body, cell_name,\n",
      "  File \"/opt/tljh/user/lib/python3.8/site-packages/IPython/core/interactiveshell.py\", line 3282, in run_ast_nodes\n",
      "    self.showtraceback()\n",
      "  File \"/opt/tljh/user/lib/python3.8/site-packages/IPython/core/interactiveshell.py\", line 2046, in showtraceback\n",
      "    stb = self.InteractiveTB.structured_traceback(etype,\n",
      "  File \"/opt/tljh/user/lib/python3.8/site-packages/IPython/core/ultratb.py\", line 1435, in structured_traceback\n",
      "    return FormattedTB.structured_traceback(\n",
      "  File \"/opt/tljh/user/lib/python3.8/site-packages/IPython/core/ultratb.py\", line 1335, in structured_traceback\n",
      "    return VerboseTB.structured_traceback(\n",
      "  File \"/opt/tljh/user/lib/python3.8/site-packages/IPython/core/ultratb.py\", line 1210, in structured_traceback\n",
      "    formatted_exceptions += self.format_exception_as_a_whole(etype, evalue, etb, lines_of_context,\n",
      "  File \"/opt/tljh/user/lib/python3.8/site-packages/IPython/core/ultratb.py\", line 1150, in format_exception_as_a_whole\n",
      "    last_unique, recursion_repeat = find_recursion(orig_etype, evalue, records)\n",
      "  File \"/opt/tljh/user/lib/python3.8/site-packages/IPython/core/ultratb.py\", line 451, in find_recursion\n",
      "    return len(records), 0\n",
      "TypeError: object of type 'NoneType' has no len()\n",
      "\n",
      "During handling of the above exception, another exception occurred:\n",
      "\n",
      "Traceback (most recent call last):\n",
      "  File \"/opt/tljh/user/lib/python3.8/site-packages/IPython/core/interactiveshell.py\", line 2044, in showtraceback\n",
      "    stb = value._render_traceback_()\n",
      "AttributeError: 'TypeError' object has no attribute '_render_traceback_'\n",
      "\n",
      "During handling of the above exception, another exception occurred:\n",
      "\n",
      "Traceback (most recent call last):\n",
      "  File \"/opt/tljh/user/lib/python3.8/site-packages/IPython/core/ultratb.py\", line 1169, in get_records\n",
      "    return _fixed_getinnerframes(etb, number_of_lines_of_context, tb_offset)\n",
      "  File \"/opt/tljh/user/lib/python3.8/site-packages/IPython/core/ultratb.py\", line 316, in wrapped\n",
      "    return f(*args, **kwargs)\n",
      "  File \"/opt/tljh/user/lib/python3.8/site-packages/IPython/core/ultratb.py\", line 350, in _fixed_getinnerframes\n",
      "    records = fix_frame_records_filenames(inspect.getinnerframes(etb, context))\n",
      "  File \"/opt/tljh/user/lib/python3.8/inspect.py\", line 1503, in getinnerframes\n",
      "    frameinfo = (tb.tb_frame,) + getframeinfo(tb, context)\n",
      "  File \"/opt/tljh/user/lib/python3.8/inspect.py\", line 1461, in getframeinfo\n",
      "    filename = getsourcefile(frame) or getfile(frame)\n",
      "  File \"/opt/tljh/user/lib/python3.8/inspect.py\", line 708, in getsourcefile\n",
      "    if getattr(getmodule(object, filename), '__loader__', None) is not None:\n",
      "  File \"/opt/tljh/user/lib/python3.8/inspect.py\", line 737, in getmodule\n",
      "    file = getabsfile(object, _filename)\n",
      "  File \"/opt/tljh/user/lib/python3.8/inspect.py\", line 721, in getabsfile\n",
      "    return os.path.normcase(os.path.abspath(_filename))\n",
      "  File \"/opt/tljh/user/lib/python3.8/posixpath.py\", line 379, in abspath\n",
      "    cwd = os.getcwd()\n",
      "FileNotFoundError: [Errno 2] No such file or directory\n"
     ]
    }
   ],
   "source": [
    "# Initialize a variable and print\n",
    "non_traffic_citations = pd.read_csv(\"NonTrafficCitations.csv\") # index_col=\"_id\")\n",
    "non_traffic_citations"
   ]
  },
  {
   "cell_type": "markdown",
   "metadata": {},
   "source": [
    "----\n",
    "### Filtering the Data\n",
    "After loading the entire data, I am going to display only the neighborhood column."
   ]
  },
  {
   "cell_type": "code",
   "execution_count": null,
   "metadata": {},
   "outputs": [],
   "source": [
    "# Display only the column with the neighborhood\n",
    "neighborhoods = non_traffic_citations.iloc[:, 8]\n",
    "neighborhoods"
   ]
  },
  {
   "cell_type": "markdown",
   "metadata": {},
   "source": [
    "----\n",
    "### Getting the number of times a citation was issued in a particular neighborhood\n",
    "The following code is going to include a dictionary. It will keep track of the number of times a citation was issued in a particular neighborhood. "
   ]
  },
  {
   "cell_type": "code",
   "execution_count": null,
   "metadata": {},
   "outputs": [],
   "source": [
    "# inDict Function\n",
    "def inDict(word):\n",
    "    for w in dictionary:\n",
    "        if word == w:\n",
    "            return True\n",
    "    return False\n",
    "\n",
    "# Initialize a global dictionary\n",
    "global dictionary\n",
    "dictionary = {}\n",
    "\n",
    "# Iterate this code for each row in neighborhoods\n",
    "for row in neighborhoods:\n",
    "    # If the item is in the dictionary, add 1 to its value\n",
    "    if(inDict(row)):\n",
    "        dictionary[row] += 1\n",
    "        \n",
    "    # If the item is not in the dictionary, create a new entry and initialize it to 1\n",
    "    else:\n",
    "        dictionary[row] = 1\n",
    "        \n",
    "# Sort the dictionary (this will turn it into a list of tuples)\n",
    "dictionary = sorted(dictionary.items(), key=operator.itemgetter(1))\n",
    "\n",
    "# Print the list\n",
    "for key in dictionary:\n",
    "    print(str(key[0]) + \": \" + str(key[1]))"
   ]
  },
  {
   "cell_type": "markdown",
   "metadata": {},
   "source": [
    "----\n",
    "### Creating a Histogram\n",
    "Below, I will create visualizations based on the above data, the first of which being a histogram."
   ]
  },
  {
   "cell_type": "code",
   "execution_count": null,
   "metadata": {},
   "outputs": [],
   "source": [
    "# Initialize a list\n",
    "numbers = []\n",
    "\n",
    "# Add elements to the list\n",
    "for key in dictionary:\n",
    "    numbers.append(int(key[1]))\n",
    "    \n",
    "# Create a DataFrame\n",
    "numbers = pd.DataFrame(numbers)\n",
    "\n",
    "# Create a histogram\n",
    "numbers[0].plot.hist(bins=15, grid=True)"
   ]
  },
  {
   "cell_type": "markdown",
   "metadata": {},
   "source": [
    "----\n",
    "### Creating a Box Plot\n",
    "The next visualization I am creating is a box plot."
   ]
  },
  {
   "cell_type": "code",
   "execution_count": null,
   "metadata": {},
   "outputs": [],
   "source": [
    "# Create a box plot\n",
    "numbers[0].plot.box()"
   ]
  },
  {
   "cell_type": "markdown",
   "metadata": {},
   "source": [
    "----\n",
    "### Create a Density Plot\n",
    "The final visualization I am creating is a density plot."
   ]
  },
  {
   "cell_type": "code",
   "execution_count": null,
   "metadata": {},
   "outputs": [],
   "source": [
    "# Create a density plot\n",
    "numbers[0].plot.density()"
   ]
  },
  {
   "cell_type": "markdown",
   "metadata": {},
   "source": [
    "----\n",
    "### Display Descriptive Statistics\n",
    "After creating the visualizations, I plan to display the descriptive statistics using the Pandas's describe method."
   ]
  },
  {
   "cell_type": "code",
   "execution_count": null,
   "metadata": {},
   "outputs": [],
   "source": [
    "# Displaying descriptive statistics\n",
    "numbers[0].describe()"
   ]
  },
  {
   "cell_type": "markdown",
   "metadata": {},
   "source": [
    "---\n",
    "### Data Analysis\n",
    "When looking at the data, the data appears to be unimodal and severely skewed to the right. There appear to be many outliers, such as a data point at 3032 and 1420.<br>\n",
    "The mean hovers around 129 citations per neighborhood, and the median hovers around 45.5 citations per neighborhood.<br>\n",
    "The standard deviation is around 341.7 citations per neighborhood, and the interquartile range is around 115.5 citations per neighborhood.<br>\n",
    "Due to the skewed distribution of the data, the median and interquartile range would be more suitable to use than the mean and standard deviation for further analysis."
   ]
  },
  {
   "cell_type": "markdown",
   "metadata": {},
   "source": [
    "----\n",
    "### Conclusion\n",
    "When looking at the data, it appears that the minimum value is a tie between multiple different neighborhoods: Ridgemont, Mount Oliver Borough,<br> \n",
    "and Chartiers City. (I decided to exclude \"nan\" in the dataset for the purpose of this conclusion.)<br>\n",
    "\n",
    "The metric our group is using is determining which neighborhood in Pittsburgh is the easiest to commit a crime in. We decided that lower<br>\n",
    "number of citations signify that committing crime is easier since this could mean that crimes may not be caught as easily.<br>\n",
    "\n",
    "Therefore, based on the data from my analysis, it appears that the easiest neighborhoods to commit a crime in are Ridgemont, Mount Oliver Borough,<br>\n",
    "and Chartiers City. However, there are many other neighborhoods with less than 10 citations, so this could also mean committing crime in those<br>\n",
    "neighborhoods may not be much more difficult than the aforementioned top three. Additionally, a lower population in these neighborhoods could also<br>\n",
    "be a factor that contributes to the low number of citations."
   ]
  },
  {
   "cell_type": "code",
   "execution_count": null,
   "metadata": {},
   "outputs": [],
   "source": []
  }
 ],
 "metadata": {
  "kernelspec": {
   "display_name": "Python 3",
   "language": "python",
   "name": "python3"
  },
  "language_info": {
   "codemirror_mode": {
    "name": "ipython",
    "version": 3
   },
   "file_extension": ".py",
   "mimetype": "text/x-python",
   "name": "python",
   "nbconvert_exporter": "python",
   "pygments_lexer": "ipython3",
   "version": "3.8.3"
  }
 },
 "nbformat": 4,
 "nbformat_minor": 4
}
